Workbook

Sheet 说明
A1: 持仓QDII基金 2026Q2 持仓跟踪
A3: 检查时间 | B3: 2026-07-21 12:25:11 +08:00
A4: 账户范围 | B4: 当前天天基金账户持有的8个份额代码，按4个底层基金家族去重。
A5: 披露结论 | B5: 4个底层基金均已公布2026年第2季度报告；截至检查时未发现2026年半年报。
A6: 披露边界 | B6: 季度报告仅披露前十大股票/存托凭证、前十名基金投资、主要债券和资产配置，不等同完整持仓。
A7: 数据来源 | B7: 基金公司法定季度报告PDF；天天基金TTFUND_HOLDING_INFO用于Q1/Q2结构化对比。
A10: 基金家族 | B10: A份额 | C10: C份额 | D10: Q2公告日 | E10: 报告期 | F10: 本地PDF | G10: 网页来源
A11: 天弘全球新能源汽车股票(QDII-LOF) | B11: 164212 | C11: 016823 | D11: 2026-07-21 | E11: 2026-06-30 | F11: D:\vcp_hunter\产业链投研\artifacts\fund_tracking\q2_2026_164212.pdf | G11: https://pdf.dfcfw.com/pdf/H2_AN202607201827148844_1.pdf
A12: 富国全球科技互联网股票(QDII) | B12: 100055 | C12: 022184 | D12: 2026-07-21 | E12: 2026-06-30 | F12: D:\vcp_hunter\产业链投研\artifacts\fund_tracking\q2_2026_100055.pdf | G12: https://pdf.dfcfw.com/pdf/H2_AN202607211827194882_1.pdf
A13: 嘉实全球产业升级股票发起式(QDII) | B13: 017730 | C13: 017731 | D13: 2026-07-21 | E13: 2026-06-30 | F13: D:\vcp_hunter\产业链投研\artifacts\fund_tracking\q2_2026_017730.pdf | G13: https://pdf.dfcfw.com/pdf/H2_AN202607211827195101_1.pdf
A14: 天弘全球高端制造混合(QDII) | B14: 016664 | C14: 016665 | D14: 2026-07-21 | E14: 2026-06-30 | F14: D:\vcp_hunter\产业链投研\artifacts\fund_tracking\q2_2026_016664.pdf | G14: https://pdf.dfcfw.com/pdf/H2_AN202607211827183829_1.pdf

Sheet 概览
A1: 基金家族 | B1: A份额 | C1: C份额 | D1: Q1股票仓位 | E1: Q2股票仓位 | F1: 仓位变化 | G1: Q2前十大合计 | H1: Q2基金投资合计 | I1: Q2债券合计 | J1: Q2核心变化
A2: 天弘全球新能源汽车股票(QDII-LOF) | B2: 164212 | C2: 016823 | D2: 0.8585 | E2: 0.8607 | F2: =E2-D2 | G2: =SUMIF('Q2前十大'!$A:$A,A2,'Q2前十大'!$J:$J) | H2: =SUMIF('Q2基金投资'!$A:$A,A2,'Q2基金投资'!$F:$F) | I2: =SUMIF('Q2债券'!$A:$A,A2,'Q2债券'!$G:$G) | J2: 前十大切换至AI算力、存储、半导体设备与车规芯片；两只韩国2X产品合计6.77%。
A3: 富国全球科技互联网股票(QDII) | B3: 100055 | C3: 022184 | D3: 0.6964 | E3: 0.9225 | F3: =E3-D3 | G3: =SUMIF('Q2前十大'!$A:$A,A3,'Q2前十大'!$J:$J) | H3: =SUMIF('Q2基金投资'!$A:$A,A3,'Q2基金投资'!$F:$F) | I3: =SUMIF('Q2债券'!$A:$A,A3,'Q2债券'!$G:$G) | J3: 从大型互联网平台显著转向存储产业链；海力士、三星、铠侠、美光、闪迪、希捷、西部数据进入前十大。
A4: 嘉实全球产业升级股票发起式(QDII) | B4: 017730 | C4: 017731 | D4: 0.8325 | E4: 0.8521 | F4: =E4-D4 | G4: =SUMIF('Q2前十大'!$A:$A,A4,'Q2前十大'!$J:$J) | H4: =SUMIF('Q2基金投资'!$A:$A,A4,'Q2基金投资'!$F:$F) | I4: =SUMIF('Q2债券'!$A:$A,A4,'Q2债券'!$G:$G) | J4: 集中于AI半导体、存储、设备和国产算力芯片；信息技术行业占净值82.99%。
A5: 天弘全球高端制造混合(QDII) | B5: 016664 | C5: 016665 | D5: 0.7908 | E5: 0.8103 | F5: =E5-D5 | G5: =SUMIF('Q2前十大'!$A:$A,A5,'Q2前十大'!$J:$J) | H5: =SUMIF('Q2基金投资'!$A:$A,A5,'Q2基金投资'!$F:$F) | I5: =SUMIF('Q2债券'!$A:$A,A5,'Q2债券'!$G:$G) | J5: AI高端制造链为主，覆盖铠侠、PCB、光模块、GPU、晶圆代工；两只韩国2X产品合计8.94%。

Sheet Q2前十大
A1: 基金家族 | B1: 基金代码 | C1: 报告期 | D1: 排名 | E1: 证券代码 | F1: 证券名称 | G1: 行业 | H1: 市场代码 | I1: 持仓市值(万元) | J1: 占净值比 | K1: 较Q1变化 | L1: 变化类型 | M1: 来源
A2: 天弘全球新能源汽车股票(QDII-LOF) | B2: 164212 | C2: 2026-06-30 | D2: 1 | E2: GLW | F2: 康宁 | H2: 106 | I2: 9568.395 | J2: 0.05 | K2: 0.05 | L2: 新增 | M2: https://pdf.dfcfw.com/pdf/H2_AN202607201827148844_1.pdf
A3: 天弘全球新能源汽车股票(QDII-LOF) | B3: 164212 | C3: 2026-06-30 | D3: 2 | E3: MRVL | F3: 迈威尔科技 | H3: 105 | I3: 7953.2841 | J3: 0.0415 | K3: 0.0415 | L3: 新增 | M3: https://pdf.dfcfw.com/pdf/H2_AN202607201827148844_1.pdf
A4: 天弘全球新能源汽车股票(QDII-LOF) | B4: 164212 | C4: 2026-06-30 | D4: 3 | E4: MU | F4: 美光科技 | H4: 105 | I4: 7625.9011 | J4: 0.0398 | K4: 0.0398 | L4: 新增 | M4: https://pdf.dfcfw.com/pdf/H2_AN202607201827148844_1.pdf
A5: 天弘全球新能源汽车股票(QDII-LOF) | B5: 164212 | C5: 2026-06-30 | D5: 4 | E5: AMD | F5: 超威半导体 | H5: 105 | I5: 6330.4319 | J5: 0.0331 | K5: 0 | L5: 不变 | M5: https://pdf.dfcfw.com/pdf/H2_AN202607201827148844_1.pdf
A6: 天弘全球新能源汽车股票(QDII-LOF) | B6: 164212 | C6: 2026-06-30 | D6: 5 | E6: TER | F6: 泰瑞达 | H6: 105 | I6: 4284.0016 | J6: 0.0224 | K6: -0.0159 | L6: 减持 | M6: https://pdf.dfcfw.com/pdf/H2_AN202607201827148844_1.pdf
A7: 天弘全球新能源汽车股票(QDII-LOF) | B7: 164212 | C7: 2026-06-30 | D7: 6 | E7: LITE | F7: Lumentum Holdings Inc | H7: 105 | I7: 4207.7958 | J7: 0.022 | K7: -0.0195 | L7: 减持 | M7: https://pdf.dfcfw.com/pdf/H2_AN202607201827148844_1.pdf
A8: 天弘全球新能源汽车股票(QDII-LOF) | B8: 164212 | C8: 2026-06-30 | D8: 7 | E8: AMAT | F8: 应用材料 | H8: 105 | I8: 4185.6386 | J8: 0.0219 | K8: 0.0219 | L8: 新增 | M8: https://pdf.dfcfw.com/pdf/H2_AN202607201827148844_1.pdf
A9: 天弘全球新能源汽车股票(QDII-LOF) | B9: 164212 | C9: 2026-06-30 | D9: 8 | E9: COHR | F9: Coherent Corp | H9: 106 | I9: 3895.7088 | J9: 0.0203 | K9: -0.0131 | L9: 减持 | M9: https://pdf.dfcfw.com/pdf/H2_AN202607201827148844_1.pdf
A10: 天弘全球新能源汽车股票(QDII-LOF) | B10: 164212 | C10: 2026-06-30 | D10: 9 | E10: STM | F10: 意法半导体 | H10: 106 | I10: 3774.5054 | J10: 0.0197 | K10: 0.0197 | L10: 新增 | M10: https://pdf.dfcfw.com/pdf/H2_AN202607201827148844_1.pdf
A11: 天弘全球新能源汽车股票(QDII-LOF) | B11: 164212 | C11: 2026-06-30 | D11: 10 | E11: 01347 | F11: 华虹宏力 | G11: 电子 | H11: 116 | I11: 3738.2392 | J11: 0.0195 | K11: 0.0195 | L11: 新增 | M11: https://pdf.dfcfw.com/pdf/H2_AN202607201827148844_1.pdf
A12: 富国全球科技互联网股票(QDII) | B12: 100055 | C12: 2026-06-30 | D12: 1 | E12: 00522 | F12: ASMPT | G12: 电子 | H12: 116 | I12: 103704.87 | J12: 0.0562 | K12: -0.0067 | L12: 减持 | M12: https://pdf.dfcfw.com/pdf/H2_AN202607211827194882_1.pdf
A13: 富国全球科技互联网股票(QDII) | B13: 100055 | C13: 2026-06-30 | D13: 2 | E13: 603986 | F13: 兆易创新 | G13: 电子 | H13: 1 | I13: 101565.3 | J13: 0.0551 | K13: 0.0551 | L13: 新增 | M13: https://pdf.dfcfw.com/pdf/H2_AN202607211827194882_1.pdf
A14: 富国全球科技互联网股票(QDII) | B14: 100055 | C14: 2026-06-30 | D14: 3 | E14: SNDK | F14: 闪迪 | H14: 105 | I14: 92916.886 | J14: 0.0504 | K14: 0.0504 | L14: 新增 | M14: https://pdf.dfcfw.com/pdf/H2_AN202607211827194882_1.pdf
A15: 富国全球科技互联网股票(QDII) | B15: 100055 | C15: 2026-06-30 | D15: 4 | E15: 600183 | F15: 生益科技 | G15: 电子 | H15: 1 | I15: 86712.884 | J15: 0.047 | K15: 0.047 | L15: 新增 | M15: https://pdf.dfcfw.com/pdf/H2_AN202607211827194882_1.pdf
A16: 富国全球科技互联网股票(QDII) | B16: 100055 | C16: 2026-06-30 | D16: 5 | E16: 000660 | F16: SK海力士 | I16: 85098.858 | J16: 0.0462 | K16: 0.0051 | L16: 增持 | M16: https://pdf.dfcfw.com/pdf/H2_AN202607211827194882_1.pdf
A17: 富国全球科技互联网股票(QDII) | B17: 100055 | C17: 2026-06-30 | D17: 6 | E17: 005930 | F17: 三星电子 | I17: 84482.997 | J17: 0.0458 | K17: 0.0125 | L17: 增持 | M17: https://pdf.dfcfw.com/pdf/H2_AN202607211827194882_1.pdf
A18: 富国全球科技互联网股票(QDII) | B18: 100055 | C18: 2026-06-30 | D18: 7 | E18: 285A | F18: KIOXIA | I18: 84461.341 | J18: 0.0458 | K18: 0.0458 | L18: 新增 | M18: https://pdf.dfcfw.com/pdf/H2_AN202607211827194882_1.pdf
A19: 富国全球科技互联网股票(QDII) | B19: 100055 | C19: 2026-06-30 | D19: 8 | E19: MU | F19: 美光科技 | H19: 105 | I19: 79403.713 | J19: 0.0431 | K19: 0.0431 | L19: 新增 | M19: https://pdf.dfcfw.com/pdf/H2_AN202607211827194882_1.pdf
A20: 富国全球科技互联网股票(QDII) | B20: 100055 | C20: 2026-06-30 | D20: 9 | E20: STX | F20: 希捷科技 | H20: 105 | I20: 78870.222 | J20: 0.0428 | K20: 0.0428 | L20: 新增 | M20: https://pdf.dfcfw.com/pdf/H2_AN202607211827194882_1.pdf
A21: 富国全球科技互联网股票(QDII) | B21: 100055 | C21: 2026-06-30 | D21: 10 | E21: WDC | F21: 西部数据 | H21: 105 | I21: 77869.619 | J21: 0.0422 | K21: 0.0422 | L21: 新增 | M21: https://pdf.dfcfw.com/pdf/H2_AN202607211827194882_1.pdf
A22: 嘉实全球产业升级股票发起式(QDII) | B22: 017730 | C22: 2026-06-30 | D22: 1 | E22: AMD | F22: 超威半导体 | H22: 105 | I22: 24530.423 | J22: 0.0354 | K22: 0.0021 | L22: 增持 | M22: https://pdf.dfcfw.com/pdf/H2_AN202607211827195101_1.pdf
A23: 嘉实全球产业升级股票发起式(QDII) | B23: 017730 | C23: 2026-06-30 | D23: 2 | E23: MU | F23: 美光科技 | H23: 105 | I23: 23585.261 | J23: 0.034 | K23: -0.0145 | L23: 减持 | M23: https://pdf.dfcfw.com/pdf/H2_AN202607211827195101_1.pdf
A24: 嘉实全球产业升级股票发起式(QDII) | B24: 017730 | C24: 2026-06-30 | D24: 3 | E24: KLAC | F24: 科磊 | H24: 105 | I24: 22193.1 | J24: 0.032 | K24: -0.0024 | L24: 减持 | M24: https://pdf.dfcfw.com/pdf/H2_AN202607211827195101_1.pdf
A25: 嘉实全球产业升级股票发起式(QDII) | B25: 017730 | C25: 2026-06-30 | D25: 4 | E25: 688498 | F25: 源杰科技 | G25: 电子 | H25: 1 | I25: 21916.64 | J25: 0.0316 | K25: -0.0109 | L25: 减持 | M25: https://pdf.dfcfw.com/pdf/H2_AN202607211827195101_1.pdf
A26: 嘉实全球产业升级股票发起式(QDII) | B26: 017730 | C26: 2026-06-30 | D26: 5 | E26: MPWR | F26: Monolithic Power Systems Inc | H26: 105 | I26: 21786.578 | J26: 0.0314 | K26: 0.0314 | L26: 新增 | M26: https://pdf.dfcfw.com/pdf/H2_AN202607211827195101_1.pdf
A27: 嘉实全球产业升级股票发起式(QDII) | B27: 017730 | C27: 2026-06-30 | D27: 6 | E27: TSM | F27: 台积电 | H27: 106 | I27: 21142.43 | J27: 0.0305 | K27: -0.0034 | L27: 减持 | M27: https://pdf.dfcfw.com/pdf/H2_AN202607211827195101_1.pdf
A28: 嘉实全球产业升级股票发起式(QDII) | B28: 017730 | C28: 2026-06-30 | D28: 7 | E28: 688361 | F28: 中科飞测 | G28: 电子 | H28: 1 | I28: 21112.484 | J28: 0.0304 | K28: 0.0304 | L28: 新增 | M28: https://pdf.dfcfw.com/pdf/H2_AN202607211827195101_1.pdf
A29: 嘉实全球产业升级股票发起式(QDII) | B29: 017730 | C29: 2026-06-30 | D29: 8 | E29: 688256 | F29: 寒武纪 | G29: 电子 | H29: 1 | I29: 20332.253 | J29: 0.0293 | K29: -0.0073 | L29: 减持 | M29: https://pdf.dfcfw.com/pdf/H2_AN202607211827195101_1.pdf
A30: 嘉实全球产业升级股票发起式(QDII) | B30: 017730 | C30: 2026-06-30 | D30: 9 | E30: AVGO | F30: 博通 | H30: 105 | I30: 20325.258 | J30: 0.0293 | K30: -0.0244 | L30: 减持 | M30: https://pdf.dfcfw.com/pdf/H2_AN202607211827195101_1.pdf
A31: 嘉实全球产业升级股票发起式(QDII) | B31: 017730 | C31: 2026-06-30 | D31: 10 | E31: 03986 | F31: 兆易创新 | G31: 电子 | H31: 116 | I31: 13813.517 | J31: 0.0199 | K31: 0.0199 | L31: 新增 | M31: https://pdf.dfcfw.com/pdf/H2_AN202607211827195101_1.pdf
A32: 嘉实全球产业升级股票发起式(QDII) | B32: 017730 | C32: 2026-06-30 | D32: 10 | E32: 603986 | F32: 兆易创新 | G32: 电子 | H32: 1 | I32: 6218.45 | J32: 0.009 | K32: 0.009 | L32: 新增 | M32: https://pdf.dfcfw.com/pdf/H2_AN202607211827195101_1.pdf
A33: 天弘全球高端制造混合(QDII) | B33: 016664 | C33: 2026-06-30 | D33: 1 | E33: JP3236330001 | F33: 铠侠控股株式会社 | I33: 22623.574 | J33: 0.0388 | K33: 0.0388 | L33: 新增 | M33: https://pdf.dfcfw.com/pdf/H2_AN202607211827183829_1.pdf
A34: 天弘全球高端制造混合(QDII) | B34: 016664 | C34: 2026-06-30 | D34: 2 | E34: 02476 | F34: 胜宏科技 | G34: 电子 | H34: 116 | I34: 19374.417 | J34: 0.0333 | K34: 0.0333 | L34: 新增 | M34: https://pdf.dfcfw.com/pdf/H2_AN202607211827183829_1.pdf
A35: 天弘全球高端制造混合(QDII) | B35: 016664 | C35: 2026-06-30 | D35: 3 | E35: 300308 | F35: 中际旭创 | G35: 通信 | H35: 0 | I35: 12700 | J35: 0.0218 | K35: -0.0026 | L35: 减持 | M35: https://pdf.dfcfw.com/pdf/H2_AN202607211827183829_1.pdf
A36: 天弘全球高端制造混合(QDII) | B36: 016664 | C36: 2026-06-30 | D36: 4 | E36: NVDA | F36: 英伟达 | H36: 105 | I36: 12605.835 | J36: 0.0216 | K36: -0.0149 | L36: 减持 | M36: https://pdf.dfcfw.com/pdf/H2_AN202607211827183829_1.pdf
A37: 天弘全球高端制造混合(QDII) | B37: 016664 | C37: 2026-06-30 | D37: 5 | E37: TSM | F37: 台积电 | H37: 106 | I37: 12197.556 | J37: 0.0209 | K37: -0.0068 | L37: 减持 | M37: https://pdf.dfcfw.com/pdf/H2_AN202607211827183829_1.pdf
A38: 天弘全球高端制造混合(QDII) | B38: 016664 | C38: 2026-06-30 | D38: 6 | E38: 01347 | F38: 华虹宏力 | G38: 电子 | H38: 116 | I38: 12149.277 | J38: 0.0209 | K38: 0.0209 | L38: 新增 | M38: https://pdf.dfcfw.com/pdf/H2_AN202607211827183829_1.pdf
A39: 天弘全球高端制造混合(QDII) | B39: 016664 | C39: 2026-06-30 | D39: 7 | E39: GLW | F39: 康宁 | H39: 106 | I39: 11743.03 | J39: 0.0202 | K39: 0.0202 | L39: 新增 | M39: https://pdf.dfcfw.com/pdf/H2_AN202607211827183829_1.pdf
A40: 天弘全球高端制造混合(QDII) | B40: 016664 | C40: 2026-06-30 | D40: 8 | E40: JP3684400009 | F40: 日东纺织 | I40: 10885.451 | J40: 0.0187 | K40: -0.0017 | L40: 减持 | M40: https://pdf.dfcfw.com/pdf/H2_AN202607211827183829_1.pdf
...

Sheet Q1-Q2变动
A1: 基金家族 | B1: 基金代码 | C1: 证券代码 | D1: 证券名称 | E1: Q1占净值比 | F1: Q2占净值比 | G1: 变化 | H1: 状态
A2: 天弘全球新能源汽车股票(QDII-LOF) | B2: 164212 | C2: GLW | D2: 康宁 | E2: 0 | F2: 0.05 | G2: =F2-E2 | H2: =IF(AND(E2=0,F2>0),"新增",IF(AND(E2>0,F2=0),"退出",IF(G2>0,"增持",IF(G2<0,"减持","不变"))))
A3: 天弘全球新能源汽车股票(QDII-LOF) | B3: 164212 | C3: MRVL | D3: 迈威尔科技 | E3: 0 | F3: 0.0415 | G3: =F3-E3 | H3: =IF(AND(E3=0,F3>0),"新增",IF(AND(E3>0,F3=0),"退出",IF(G3>0,"增持",IF(G3<0,"减持","不变"))))
A4: 天弘全球新能源汽车股票(QDII-LOF) | B4: 164212 | C4: MU | D4: 美光科技 | E4: 0 | F4: 0.0398 | G4: =F4-E4 | H4: =IF(AND(E4=0,F4>0),"新增",IF(AND(E4>0,F4=0),"退出",IF(G4>0,"增持",IF(G4<0,"减持","不变"))))
A5: 天弘全球新能源汽车股票(QDII-LOF) | B5: 164212 | C5: AMD | D5: 超威半导体 | E5: 0.0331 | F5: 0.0331 | G5: =F5-E5 | H5: =IF(AND(E5=0,F5>0),"新增",IF(AND(E5>0,F5=0),"退出",IF(G5>0,"增持",IF(G5<0,"减持","不变"))))
A6: 天弘全球新能源汽车股票(QDII-LOF) | B6: 164212 | C6: TER | D6: 泰瑞达 | E6: 0.0383 | F6: 0.0224 | G6: =F6-E6 | H6: =IF(AND(E6=0,F6>0),"新增",IF(AND(E6>0,F6=0),"退出",IF(G6>0,"增持",IF(G6<0,"减持","不变"))))
A7: 天弘全球新能源汽车股票(QDII-LOF) | B7: 164212 | C7: LITE | D7: Lumentum Holdings Inc | E7: 0.0415 | F7: 0.022 | G7: =F7-E7 | H7: =IF(AND(E7=0,F7>0),"新增",IF(AND(E7>0,F7=0),"退出",IF(G7>0,"增持",IF(G7<0,"减持","不变"))))
A8: 天弘全球新能源汽车股票(QDII-LOF) | B8: 164212 | C8: AMAT | D8: 应用材料 | E8: 0 | F8: 0.0219 | G8: =F8-E8 | H8: =IF(AND(E8=0,F8>0),"新增",IF(AND(E8>0,F8=0),"退出",IF(G8>0,"增持",IF(G8<0,"减持","不变"))))
A9: 天弘全球新能源汽车股票(QDII-LOF) | B9: 164212 | C9: COHR | D9: Coherent Corp | E9: 0.0334 | F9: 0.0203 | G9: =F9-E9 | H9: =IF(AND(E9=0,F9>0),"新增",IF(AND(E9>0,F9=0),"退出",IF(G9>0,"增持",IF(G9<0,"减持","不变"))))
A10: 天弘全球新能源汽车股票(QDII-LOF) | B10: 164212 | C10: STM | D10: 意法半导体 | E10: 0 | F10: 0.0197 | G10: =F10-E10 | H10: =IF(AND(E10=0,F10>0),"新增",IF(AND(E10>0,F10=0),"退出",IF(G10>0,"增持",IF(G10<0,"减持","不变"))))
A11: 天弘全球新能源汽车股票(QDII-LOF) | B11: 164212 | C11: 01347 | D11: 华虹宏力 | E11: 0 | F11: 0.0195 | G11: =F11-E11 | H11: =IF(AND(E11=0,F11>0),"新增",IF(AND(E11>0,F11=0),"退出",IF(G11>0,"增持",IF(G11<0,"减持","不变"))))
A12: 天弘全球新能源汽车股票(QDII-LOF) | B12: 164212 | C12: NVDA | D12: 英伟达 | E12: 0.0464 | F12: 0 | G12: =F12-E12 | H12: =IF(AND(E12=0,F12>0),"新增",IF(AND(E12>0,F12=0),"退出",IF(G12>0,"增持",IF(G12<0,"减持","不变"))))
A13: 天弘全球新能源汽车股票(QDII-LOF) | B13: 164212 | C13: TSM | D13: 台积电 | E13: 0.0437 | F13: 0 | G13: =F13-E13 | H13: =IF(AND(E13=0,F13>0),"新增",IF(AND(E13>0,F13=0),"退出",IF(G13>0,"增持",IF(G13<0,"减持","不变"))))
... A64: 嘉实全球产业升级股票发起式(QDII) | B64: 017730 | C64: 603986 | D64: 兆易创新 | E64: 0 | F64: 0.009 | G64: =F64-E64 | H64: =IF(AND(E64=0,F64>0),"新增",IF(AND(E64>0,F64=0),"退出",IF(G64>0,"增持",IF(G64<0,"减持","不变"))))

Sheet Q2基金投资
A1: 基金家族 | B1: 基金代码 | C1: 被投基金代码 | D1: 被投基金名称 | E1: 公允价值(人民币) | F1: 占净值比 | G1: 说明 | H1: 来源
A2: 天弘全球新能源汽车股票(QDII-LOF) | B2: 164212 | C2: 7709.HK | D2: CSOP SK Hynix Daily 2x Leveraged Product | E2: 93178044 | F2: 0.0487 | G2: 季度报告前十名基金投资；2X产品为每日杠杆，不代表长期固定2倍。 | H2: https://pdf.dfcfw.com/pdf/H2_AN202607201827148844_1.pdf
A3: 天弘全球新能源汽车股票(QDII-LOF) | B3: 164212 | C3: 7747.HK / 9747.HK | D3: CSOP Samsung Electronics Daily 2x Leveraged Product | E3: 36370531 | F3: 0.019 | G3: 季度报告前十名基金投资；2X产品为每日杠杆，不代表长期固定2倍。 | H3: https://pdf.dfcfw.com/pdf/H2_AN202607201827148844_1.pdf
A4: 富国全球科技互联网股票(QDII) | B4: 100055 | C4: N/A | D4: 南方港韩科技 | E4: 1.4234452e+08 | F4: 0.0077 | G4: 季度报告前十名基金投资。 | H4: https://pdf.dfcfw.com/pdf/H2_AN202607211827194882_1.pdf
A5: 嘉实全球产业升级股票发起式(QDII) | B5: 017730 | C5: N/A | D5: Harvest G2 Tech 50 ETF | E5: 6415544.6 | F5: 0.0009 | G5: 季度报告前十名基金投资。 | H5: https://pdf.dfcfw.com/pdf/H2_AN202607211827195101_1.pdf
A6: 天弘全球高端制造混合(QDII) | B6: 016664 | C6: 7709.HK | D6: CSOP SK Hynix Daily 2x Leveraged Product | E6: 4.3353673e+08 | F6: 0.0744 | G6: 季度报告前十名基金投资；2X产品为每日杠杆，不代表长期固定2倍。 | H6: https://pdf.dfcfw.com/pdf/H2_AN202607211827183829_1.pdf
A7: 天弘全球高端制造混合(QDII) | B7: 016664 | C7: 7747.HK / 9747.HK | D7: CSOP Samsung Electronics Daily 2x Leveraged Product | E7: 87289275 | F7: 0.015 | G7: 季度报告前十名基金投资；2X产品为每日杠杆，不代表长期固定2倍。 | H7: https://pdf.dfcfw.com/pdf/H2_AN202607211827183829_1.pdf

Sheet Q2债券
A1: 基金家族 | B1: 基金代码 | C1: 债券代码 | D1: 债券名称 | E1: 数量/面值 | F1: 公允价值(人民币) | G1: 占净值比 | H1: 来源
A2: 天弘全球新能源汽车股票(QDII-LOF) | B2: 164212 | C2: 019792 | D2: 25国债19 | E2: 900000 | F2: 909443.1 | G2: 0.0005 | H2: https://pdf.dfcfw.com/pdf/H2_AN202607201827148844_1.pdf
A3: 嘉实全球产业升级股票发起式(QDII) | B3: 017730 | C3: 019835 | D3: 26国债09 | E3: 175600000 | F3: 1.7588899e+08 | G3: 0.0254 | H3: https://pdf.dfcfw.com/pdf/H2_AN202607211827195101_1.pdf
A4: 嘉实全球产业升级股票发起式(QDII) | B4: 017730 | C4: 019827 | D4: 26国债01 | E4: 123900000 | F4: 1.2470311e+08 | G4: 0.018 | H4: https://pdf.dfcfw.com/pdf/H2_AN202607211827195101_1.pdf
A5: 嘉实全球产业升级股票发起式(QDII) | B5: 017730 | C5: 019785 | D5: 25国债13 | E5: 36000000 | F5: 36454517 | G5: 0.0053 | H5: https://pdf.dfcfw.com/pdf/H2_AN202607211827195101_1.pdf
A6: 嘉实全球产业升级股票发起式(QDII) | B6: 017730 | C6: 019792 | D6: 25国债19 | E6: 7000000 | F6: 7073446.3 | G6: 0.001 | H6: https://pdf.dfcfw.com/pdf/H2_AN202607211827195101_1.pdf
A7: 天弘全球高端制造混合(QDII) | B7: 016664 | C7: 260411 | D7: 26农发11 | E7: 90000000 | F7: 90437178 | G7: 0.0155 | H7: https://pdf.dfcfw.com/pdf/H2_AN202607211827183829_1.pdf

Sheet Q2资产配置
A1: 基金家族 | B1: 基金代码 | C1: 报告期 | D1: 项目 | E1: 金额(人民币) | F1: 占总资产比 | G1: 来源
A2: 天弘全球新能源汽车股票(QDII-LOF) | B2: 164212 | C2: 2026-06-30 | D2: 权益投资 | E2: 1.6477783e+09 | F2: 0.8185 | G2: https://pdf.dfcfw.com/pdf/H2_AN202607201827148844_1.pdf
A3: 天弘全球新能源汽车股票(QDII-LOF) | B3: 164212 | C3: 2026-06-30 | D3: 基金投资 | E3: 1.2954858e+08 | F3: 0.0643 | G3: https://pdf.dfcfw.com/pdf/H2_AN202607201827148844_1.pdf
A4: 天弘全球新能源汽车股票(QDII-LOF) | B4: 164212 | C4: 2026-06-30 | D4: 固定收益投资 | E4: 909443.1 | F4: 0.0005 | G4: https://pdf.dfcfw.com/pdf/H2_AN202607201827148844_1.pdf
A5: 天弘全球新能源汽车股票(QDII-LOF) | B5: 164212 | C5: 2026-06-30 | D5: 银行存款和结算备付金 | E5: 1.2878399e+08 | F5: 0.064 | G5: https://pdf.dfcfw.com/pdf/H2_AN202607201827148844_1.pdf
A6: 天弘全球新能源汽车股票(QDII-LOF) | B6: 164212 | C6: 2026-06-30 | D6: 其他资产 | E6: 1.0624001e+08 | F6: 0.0528 | G6: https://pdf.dfcfw.com/pdf/H2_AN202607201827148844_1.pdf
A7: 富国全球科技互联网股票(QDII) | B7: 100055 | C7: 2026-06-30 | D7: 权益投资 | E7: 1.700704e+10 | F7: 0.8704 | G7: https://pdf.dfcfw.com/pdf/H2_AN202607211827194882_1.pdf
A8: 富国全球科技互联网股票(QDII) | B8: 100055 | C8: 2026-06-30 | D8: 基金投资 | E8: 1.4234452e+08 | F8: 0.0073 | G8: https://pdf.dfcfw.com/pdf/H2_AN202607211827194882_1.pdf
A9: 富国全球科技互联网股票(QDII) | B9: 100055 | C9: 2026-06-30 | D9: 固定收益投资 | E9: 0 | F9: 0 | G9: https://pdf.dfcfw.com/pdf/H2_AN202607211827194882_1.pdf
A10: 富国全球科技互联网股票(QDII) | B10: 100055 | C10: 2026-06-30 | D10: 银行存款和结算备付金 | E10: 1.9939804e+09 | F10: 0.102 | G10: https://pdf.dfcfw.com/pdf/H2_AN202607211827194882_1.pdf
A11: 富国全球科技互联网股票(QDII) | B11: 100055 | C11: 2026-06-30 | D11: 其他资产 | E11: 3.960612e+08 | F11: 0.0203 | G11: https://pdf.dfcfw.com/pdf/H2_AN202607211827194882_1.pdf
A12: 嘉实全球产业升级股票发起式(QDII) | B12: 017730 | C12: 2026-06-30 | D12: 权益投资 | E12: 5.9119092e+09 | F12: 0.812 | G12: https://pdf.dfcfw.com/pdf/H2_AN202607211827195101_1.pdf
A13: 嘉实全球产业升级股票发起式(QDII) | B13: 017730 | C13: 2026-06-30 | D13: 基金投资 | E13: 6415544.6 | F13: 0.0009 | G13: https://pdf.dfcfw.com/pdf/H2_AN202607211827195101_1.pdf
... A21: 天弘全球高端制造混合(QDII) | B21: 016664 | C21: 2026-06-30 | D21: 其他资产 | E21: 1.7413629e+08 | F21: 0.0291 | G21: https://pdf.dfcfw.com/pdf/H2_AN202607211827183829_1.pdf

Sheet Q2地区行业
A1: 基金家族 | B1: 基金代码 | C1: 报告期 | D1: 分类 | E1: 项目 | F1: 公允价值(人民币) | G1: 占净值比 | H1: 来源
A2: 天弘全球新能源汽车股票(QDII-LOF) | B2: 164212 | C2: 2026-06-30 | D2: 地区 | E2: 美国 | F2: 8.4592845e+08 | G2: 0.4419 | H2: https://pdf.dfcfw.com/pdf/H2_AN202607201827148844_1.pdf
A3: 天弘全球新能源汽车股票(QDII-LOF) | B3: 164212 | C3: 2026-06-30 | D3: 地区 | E3: 中国 | F3: 6.8561484e+08 | G3: 0.3581 | H3: https://pdf.dfcfw.com/pdf/H2_AN202607201827148844_1.pdf
A4: 天弘全球新能源汽车股票(QDII-LOF) | B4: 164212 | C4: 2026-06-30 | D4: 地区 | E4: 中国香港 | F4: 1.1623498e+08 | G4: 0.0607 | H4: https://pdf.dfcfw.com/pdf/H2_AN202607201827148844_1.pdf
A5: 天弘全球新能源汽车股票(QDII-LOF) | B5: 164212 | C5: 2026-06-30 | D5: 行业 | E5: 信息技术 | F5: 1278484088 | G5: 0.6678 | H5: https://pdf.dfcfw.com/pdf/H2_AN202607201827148844_1.pdf
A6: 天弘全球新能源汽车股票(QDII-LOF) | B6: 164212 | C6: 2026-06-30 | D6: 行业 | E6: 基础材料 | F6: 241578100 | G6: 0.1262 | H6: https://pdf.dfcfw.com/pdf/H2_AN202607201827148844_1.pdf
A7: 天弘全球新能源汽车股票(QDII-LOF) | B7: 164212 | C7: 2026-06-30 | D7: 行业 | E7: 工业 | F7: 98167059 | G7: 0.0513 | H7: https://pdf.dfcfw.com/pdf/H2_AN202607201827148844_1.pdf
A8: 天弘全球新能源汽车股票(QDII-LOF) | B8: 164212 | C8: 2026-06-30 | D8: 行业 | E8: 消费者非必需品 | F8: 28940690 | G8: 0.0151 | H8: https://pdf.dfcfw.com/pdf/H2_AN202607201827148844_1.pdf
A9: 天弘全球新能源汽车股票(QDII-LOF) | B9: 164212 | C9: 2026-06-30 | D9: 行业 | E9: 公用事业 | F9: 383765.49 | G9: 0.0002 | H9: https://pdf.dfcfw.com/pdf/H2_AN202607201827148844_1.pdf
A10: 天弘全球新能源汽车股票(QDII-LOF) | B10: 164212 | C10: 2026-06-30 | D10: 行业 | E10: 其他-GICS未分类 | F10: 224572.69 | G10: 0.0001 | H10: https://pdf.dfcfw.com/pdf/H2_AN202607201827148844_1.pdf
A11: 富国全球科技互联网股票(QDII) | B11: 100055 | C11: 2026-06-30 | D11: 地区 | E11: 中国香港 | F11: 9.2753506e+09 | G11: 0.5031 | H11: https://pdf.dfcfw.com/pdf/H2_AN202607211827194882_1.pdf
A12: 富国全球科技互联网股票(QDII) | B12: 100055 | C12: 2026-06-30 | D12: 地区 | E12: 美国 | F12: 3.2906044e+09 | G12: 0.1785 | H12: https://pdf.dfcfw.com/pdf/H2_AN202607211827194882_1.pdf
A13: 富国全球科技互联网股票(QDII) | B13: 100055 | C13: 2026-06-30 | D13: 地区 | E13: 中国大陆 | F13: 1.9006533e+09 | G13: 0.1031 | H13: https://pdf.dfcfw.com/pdf/H2_AN202607211827194882_1.pdf
... A42: 天弘全球高端制造混合(QDII) | B42: 016664 | C42: 2026-06-30 | D42: 行业 | E42: 其他-GICS未分类 | F42: 276926.93 | G42: 0 | H42: https://pdf.dfcfw.com/pdf/H2_AN202607211827183829_1.pdf

Sheet 公告检查
A1: 检查时间 | B1: A份额 | C1: C份额 | D1: 基金家族 | E1: 最新报告 | F1: 公告日 | G1: 报告期 | H1: Q2状态 | I1: 半年报状态 | J1: 来源
A2: 2026-07-21 12:25:11 +08:00 | B2: 164212 | C2: 016823 | D2: 天弘全球新能源汽车股票(QDII-LOF) | E2: 天弘全球新能源汽车股票型证券投资基金(QDII-LOF)2026年第2季度报告 | F2: 2026-07-21 | G2: 2026-06-30 | H2: 已公布并更新 | I2: 未发现 | J2: https://pdf.dfcfw.com/pdf/H2_AN202607201827148844_1.pdf
A3: 2026-07-21 12:25:11 +08:00 | B3: 100055 | C3: 022184 | D3: 富国全球科技互联网股票(QDII) | E3: 富国全球科技互联网股票型证券投资基金(QDII)二0二六年第2季度报告 | F3: 2026-07-21 | G3: 2026-06-30 | H3: 已公布并更新 | I3: 未发现 | J3: https://pdf.dfcfw.com/pdf/H2_AN202607211827194882_1.pdf
A4: 2026-07-21 12:25:11 +08:00 | B4: 017730 | C4: 017731 | D4: 嘉实全球产业升级股票发起式(QDII) | E4: 嘉实全球产业升级股票型发起式证券投资基金(QDII)2026年第2季度报告 | F4: 2026-07-21 | G4: 2026-06-30 | H4: 已公布并更新 | I4: 未发现 | J4: https://pdf.dfcfw.com/pdf/H2_AN202607211827195101_1.pdf
A5: 2026-07-21 12:25:11 +08:00 | B5: 016664 | C5: 016665 | D5: 天弘全球高端制造混合(QDII) | E5: 天弘全球高端制造混合型证券投资基金(QDII)2026年第2季度报告 | F5: 2026-07-21 | G5: 2026-06-30 | H5: 已公布并更新 | I5: 未发现 | J5: https://pdf.dfcfw.com/pdf/H2_AN202607211827183829_1.pdf
